
C:\Users\Msys\OneDrive\Desktop\axox-acadmy\python Stack\django\django_intro\Project(master -> origin) (venv) λ django-admin startproject Books_Authors

C:\Users\Msys\OneDrive\Desktop\axox-acadmy\python Stack\django\django_intro\Project(master -> origin) (venv) λ cd Books_Authors

C:\Users\Msys\OneDrive\Desktop\axox-acadmy\python Stack\django\django_intro\Project\Books_Authors(master -> origin)
(venv) λ py manage.py startapp library

C:\Users\Msys\OneDrive\Desktop\axox-acadmy\python Stack\django\django_intro\Project\Books_Authors(master -> origin)
(venv) λ code .

C:\Users\Msys\OneDrive\Desktop\axox-acadmy\python Stack\django\django_intro\Project\Books_Authors(master -> origin)
(venv) λ python manage.py makemigrations
Migrations for 'library':
  library\migrations\0001_initial.py
    - Create model Book
    - Create model Publisher

C:\Users\Msys\OneDrive\Desktop\axox-acadmy\python Stack\django\django_intro\Project\Books_Authors(master -> origin)
(venv) λ python manage.py migrate
Operations to perform:
  Apply all migrations: admin, auth, contenttypes, library, sessions
Running migrations:
  Applying contenttypes.0001_initial... OK
  Applying auth.0001_initial... OK
  Applying admin.0001_initial... OK
  Applying admin.0002_logentry_remove_auto_add... OK
  Applying admin.0003_logentry_add_action_flag_choices... OK
  Applying contenttypes.0002_remove_content_type_name... OK
  Applying auth.0002_alter_permission_name_max_length... OK
  Applying auth.0003_alter_user_email_max_length... OK
  Applying auth.0004_alter_user_username_opts... OK
  Applying auth.0005_alter_user_last_login_null... OK
  Applying auth.0006_require_contenttypes_0002... OK
  Applying auth.0007_alter_validators_add_error_messages... OK
  Applying auth.0008_alter_user_username_max_length... OK
  Applying auth.0009_alter_user_last_name_max_length... OK
  Applying auth.0010_alter_group_name_max_length... OK
  Applying auth.0011_update_proxy_permissions... OK
  Applying auth.0012_alter_user_first_name_max_length... OK
  Applying library.0001_initial... OK
  Applying sessions.0001_initial... OK

C:\Users\Msys\OneDrive\Desktop\axox-acadmy\python Stack\django\django_intro\Project\Books_Authors(master -> origin)
(venv) λ python manage.py shell
Python 3.10.7 (tags/v3.10.7:6cc6b13, Sep  5 2022, 14:08:36) [MSC v.1933 64 bit (AMD64)] on win32
Type "help", "copyright", "credits" or "license" for more information.
(InteractiveConsole)
>>> from books_authors_app.models import *
Traceback (most recent call last):
  File "<console>", line 1, in <module>
ModuleNotFoundError: No module named 'books_authors_app'
>>> from library.models import *
>>> Book.objects.create(title='C Sharp',desc='Prgramming language')
Traceback (most recent call last):
  File "<console>", line 1, in <module>
  File "C:\Users\Msys\OneDrive\Desktop\axox-acadmy\python Stack\django\django_intro\Project\venv\lib\site-packages\django\db\models\manager.py", line 85, in manager_method
    return getattr(self.get_queryset(), name)(*args, **kwargs)
  File "C:\Users\Msys\OneDrive\Desktop\axox-acadmy\python Stack\django\django_intro\Project\venv\lib\site-packages\django\db\models\query.py", line 669, in create
    obj = self.model(**kwargs)
  File "C:\Users\Msys\OneDrive\Desktop\axox-acadmy\python Stack\django\django_intro\Project\venv\lib\site-packages\django\db\models\base.py", line 585, in __init__
    raise TypeError(
TypeError: Book() got unexpected keyword arguments: 'desc'
>>> Book.objects.create(title='C Sharp',desc='Prgramming language')
Traceback (most recent call last):
  File "<console>", line 1, in <module>
  File "C:\Users\Msys\OneDrive\Desktop\axox-acadmy\python Stack\django\django_intro\Project\venv\lib\site-packages\django\db\models\manager.py", line 85, in manager_method
    return getattr(self.get_queryset(), name)(*args, **kwargs)
  File "C:\Users\Msys\OneDrive\Desktop\axox-acadmy\python Stack\django\django_intro\Project\venv\lib\site-packages\django\db\models\query.py", line 669, in create
    obj = self.model(**kwargs)
  File "C:\Users\Msys\OneDrive\Desktop\axox-acadmy\python Stack\django\django_intro\Project\venv\lib\site-packages\django\db\models\base.py", line 585, in __init__
    raise TypeError(
TypeError: Book() got unexpected keyword arguments: 'desc'
>>> exit()

C:\Users\Msys\OneDrive\Desktop\axox-acadmy\python Stack\django\django_intro\Project\Books_Authors(master -> origin)
(venv) λ python manage.py makemigrations
Migrations for 'library':
  library\migrations\0002_book_desc.py
    - Add field desc to book

C:\Users\Msys\OneDrive\Desktop\axox-acadmy\python Stack\django\django_intro\Project\Books_Authors(master -> origin)
(venv) λ python manage.py migrate
Operations to perform:
  Apply all migrations: admin, auth, contenttypes, library, sessions
Running migrations:
  Applying library.0002_book_desc... OK

C:\Users\Msys\OneDrive\Desktop\axox-acadmy\python Stack\django\django_intro\Project\Books_Authors(master -> origin)
(venv) λ python manage.py shell
Python 3.10.7 (tags/v3.10.7:6cc6b13, Sep  5 2022, 14:08:36) [MSC v.1933 64 bit (AMD64)] on win32
Type "help", "copyright", "credits" or "license" for more information.
(InteractiveConsole)
>>> Book.objects.create(title='C Sharp',desc='Prgramming language')
Traceback (most recent call last):
  File "<console>", line 1, in <module>
NameError: name 'Book' is not defined
>>> from books_authors_app.models import *
Traceback (most recent call last):
  File "<console>", line 1, in <module>
ModuleNotFoundError: No module named 'books_authors_app'
>>> from library.models import *
>>> Book.objects.create(title='C Sharp',desc='Prgramming language')
<Book: Book object (1)>
>>>  Book.objects.create(title='Java',desc='Prgramming language')
  File "<console>", line 1
    Book.objects.create(title='Java',desc='Prgramming language')
IndentationError: unexpected indent
>>>  Book.objects.create(title='Java',desc='Prgramming language')
  File "<console>", line 1
    Book.objects.create(title='Java',desc='Prgramming language')
IndentationError: unexpected indent
>>> exit()

C:\Users\Msys\OneDrive\Desktop\axox-acadmy\python Stack\django\django_intro\Project\Books_Authors(master -> origin)
(venv) λ python manage.py makemigrations
No changes detected

C:\Users\Msys\OneDrive\Desktop\axox-acadmy\python Stack\django\django_intro\Project\Books_Authors(master -> origin)
(venv) λ python manage.py makemigrations
It is impossible to change a nullable field 'desc' on book to non-nullable without providing a default. This is because the database needs something to populate existing rows.
Please select a fix:
 1) Provide a one-off default now (will be set on all existing rows with a null value for this column)

 2) Ignore for now. Existing rows that contain NULL values will have to be handled manually, for example with a RunPython or RunSQL operation.
 3) Quit and manually define a default value in models.py.
Select an option: Traceback (most recent call last):
  File "C:\Users\Msys\OneDrive\Desktop\axox-acadmy\python Stack\django\django_intro\Project\Books_Authors\manage.py", line 22, in <module>
    main()
  File "C:\Users\Msys\OneDrive\Desktop\axox-acadmy\python Stack\django\django_intro\Project\Books_Authors\manage.py", line 18, in main
    execute_from_command_line(sys.argv)
  File "C:\Users\Msys\OneDrive\Desktop\axox-acadmy\python Stack\django\django_intro\Project\venv\lib\site-packages\django\core\management\__init__.py", line 446, in execute_from_command_line
    utility.execute()
  File "C:\Users\Msys\OneDrive\Desktop\axox-acadmy\python Stack\django\django_intro\Project\venv\lib\site-packages\django\core\management\__init__.py", line 440, in execute
    self.fetch_command(subcommand).run_from_argv(self.argv)
  File "C:\Users\Msys\OneDrive\Desktop\axox-acadmy\python Stack\django\django_intro\Project\venv\lib\site-packages\django\core\management\base.py", line 402, in run_from_argv
    self.execute(*args, **cmd_options)
  File "C:\Users\Msys\OneDrive\Desktop\axox-acadmy\python Stack\django\django_intro\Project\venv\lib\site-packages\django\core\management\base.py", line 448, in execute
    output = self.handle(*args, **options)
  File "C:\Users\Msys\OneDrive\Desktop\axox-acadmy\python Stack\django\django_intro\Project\venv\lib\site-packages\django\core\management\base.py", line 96, in wrapped
    res = handle_func(*args, **kwargs)
  File "C:\Users\Msys\OneDrive\Desktop\axox-acadmy\python Stack\django\django_intro\Project\venv\lib\site-packages\django\core\management\commands\makemigrations.py", line 218, in handle
    changes = autodetector.changes(
  File "C:\Users\Msys\OneDrive\Desktop\axox-acadmy\python Stack\django\django_intro\Project\venv\lib\site-packages\django\db\migrations\autodetector.py", line 46, in changes
    changes = self._detect_changes(convert_apps, graph)
  File "C:\Users\Msys\OneDrive\Desktop\axox-acadmy\python Stack\django\django_intro\Project\venv\lib\site-packages\django\db\migrations\autodetector.py", line 196, in _detect_changes
    self.generate_altered_fields()
  File "C:\Users\Msys\OneDrive\Desktop\axox-acadmy\python Stack\django\django_intro\Project\venv\lib\site-packages\django\db\migrations\autodetector.py", line 1193, in generate_altered_fields
    new_default = self.questioner.ask_not_null_alteration(
  File "C:\Users\Msys\OneDrive\Desktop\axox-acadmy\python Stack\django\django_intro\Project\venv\lib\site-packages\django\db\migrations\questioner.py", line 192, in ask_not_null_alteration
    choice = self._choice_input(
  File "C:\Users\Msys\OneDrive\Desktop\axox-acadmy\python Stack\django\django_intro\Project\venv\lib\site-packages\django\db\migrations\questioner.py", line 114, in _choice_input
    result = input()
KeyboardInterrupt
^C
C:\Users\Msys\OneDrive\Desktop\axox-acadmy\python Stack\django\django_intro\Project\Books_Authors(master -> origin)
(venv) λ python manage.py makemigrations
No changes detected

C:\Users\Msys\OneDrive\Desktop\axox-acadmy\python Stack\django\django_intro\Project\Books_Authors(master -> origin)
(venv) λ python manage.py migrate
Operations to perform:
  Apply all migrations: admin, auth, contenttypes, library, sessions
Running migrations:
  No migrations to apply.

C:\Users\Msys\OneDrive\Desktop\axox-acadmy\python Stack\django\django_intro\Project\Books_Authors(master -> origin)
(venv) λ python manage.py shell
Python 3.10.7 (tags/v3.10.7:6cc6b13, Sep  5 2022, 14:08:36) [MSC v.1933 64 bit (AMD64)] on win32
Type "help", "copyright", "credits" or "license" for more information.
(InteractiveConsole)
>>> from books_authors_app.models import *
Traceback (most recent call last):
  File "<console>", line 1, in <module>
ModuleNotFoundError: No module named 'books_authors_app'
>>> from library.models import *
>>> c=Book.objects.create(title='Java',desc='Prgramming language')
>>>  Book.objects.all()
  File "<console>", line 1
    Book.objects.all()
IndentationError: unexpected indent
>>> Book.objects.all()
<QuerySet [<Book: Book object (1)>, <Book: Book object (2)>]>
>>> Book.objects.create(title='Java',desc='Prgramming language')
<Book: Book object (3)>
>>> Book.objects.create(title='Python',desc='Prgramming language')
<Book: Book object (4)>
>>> Book.objects.create(title='PHP',desc='Prgramming language')
<Book: Book object (5)>
>>> Book.objects.create(title='Rupy',desc='Prgramming language')
<Book: Book object (6)>
>>> Book.objects.all().__dict__()
Traceback (most recent call last):
  File "<console>", line 1, in <module>
TypeError: 'dict' object is not callable
>>> Book.objects.all()
<QuerySet [<Book: Book object (1)>, <Book: Book object (2)>, <Book: Book object (3)>, <Book: Book object (4)>, <Book: Book object (5)>, <Book: Book object (6)>]>
>>> exit()

C:\Users\Msys\OneDrive\Desktop\axox-acadmy\python Stack\django\django_intro\Project\Books_Authors(master -> origin)
(venv) λ python manage.py makemigrations
Migrations for 'library':
  library\migrations\0003_author_delete_publisher.py
    - Create model Author
    - Delete model Publisher

C:\Users\Msys\OneDrive\Desktop\axox-acadmy\python Stack\django\django_intro\Project\Books_Authors(master -> origin)
(venv) λ python manage.py migrate
Operations to perform:
  Apply all migrations: admin, auth, contenttypes, library, sessions
Running migrations:
  Applying library.0003_author_delete_publisher... OK

C:\Users\Msys\OneDrive\Desktop\axox-acadmy\python Stack\django\django_intro\Project\Books_Authors(master -> origin)
(venv) λ python manage.py shell
Python 3.10.7 (tags/v3.10.7:6cc6b13, Sep  5 2022, 14:08:36) [MSC v.1933 64 bit (AMD64)] on win32
Type "help", "copyright", "credits" or "license" for more information.
(InteractiveConsole)
>>> from library.models import *
>>> Author.objects.create(first_name='Jane',last_name='Austen')
<Author: Author object (1)>
>>> Author.objects.create(first_name='Laith',last_name='Barooq')
<Author: Author object (2)>
>>> Author.objects.create(first_name='Zaki',last_name='Nahhas'))
  File "<console>", line 1
    Author.objects.create(first_name='Zaki',last_name='Nahhas'))
                                                               ^
SyntaxError: unmatched ')'
>>> Author.objects.create(first_name='Zaki',last_name='Nahhas')
<Author: Author object (3)>
>>> Author.objects.create(first_name='Amin',last_name='Elayan')
<Author: Author object (4)>
>>> Author.objects.create(first_name='yousef',last_name='Assi')
<Author: Author object (5)>
>>> exit()

C:\Users\Msys\OneDrive\Desktop\axox-acadmy\python Stack\django\django_intro\Project\Books_Authors(master -> origin)
(venv) λ python manage.py makemigrations
Migrations for 'library':
  library\migrations\0004_author_notes.py
    - Add field notes to author

C:\Users\Msys\OneDrive\Desktop\axox-acadmy\python Stack\django\django_intro\Project\Books_Authors(master -> origin)
(venv) λ python manage.py migrate
Operations to perform:
  Apply all migrations: admin, auth, contenttypes, library, sessions
Running migrations:
  Applying library.0004_author_notes... OK

C:\Users\Msys\OneDrive\Desktop\axox-acadmy\python Stack\django\django_intro\Project\Books_Authors(master -> origin)
(venv) λ python manage.py shell
Python 3.10.7 (tags/v3.10.7:6cc6b13, Sep  5 2022, 14:08:36) [MSC v.1933 64 bit (AMD64)] on win32
Type "help", "copyright", "credits" or "license" for more information.
(InteractiveConsole)
>>> from library.models import *
>>> b1=Book.objects.get(id=1)
>>> b1.title='C#'
>>> b1.save()
>>> a4=Author.objects.get(id=4)
>>> a4.first_name='Bill'
>>> a4.save()
>>> book1=Book.objects.get(id=1)
>>> book2=Book.objects.get(id=2)
>>> book2=Book.objects.get(id=3)
>>> book2=Book.objects.get(id=4)
>>> book2=Book.objects.get(id=5)
>>> author1=Author.objects.get(id=1)
>>> author1=Author.objects.get(id=2)
>>> author1=Author.objects.get(id=3)
>>> author1=Author.objects.get(id=4)
>>> author1=Author.objects.get(id=5)
>>> author1.books.add(book1)
>>> author1.books.add(book2)
>>> author2.books.add(book1)
Traceback (most recent call last):
  File "<console>", line 1, in <module>
NameError: name 'author2' is not defined
>>> book5=Book.objects.get(id=5)
>>> book4=Book.objects.get(id=4)
>>> book3=Book.objects.get(id=3)
>>> book2=Book.objects.get(id=2)
>>> author5=Author.objects.get(id=5)
>>> author4=Author.objects.get(id=4)
>>> author3=Author.objects.get(id=3)
>>> author2=Author.objects.get(id=2)
>>> author2.books.add(book1)
>>> author2.books.add(book2)
>>> author2.books.add(book3)
>>> author3.books.add(book1)
>>> author3.books.add(book2)
>>> author3.books.add(book3)
>>> author3.books.add(book4)
>>> author4.books.add(book1)
>>> author4.books.add(book2)
>>> author4.books.add(book3)
>>> author4.books.add(book4)
>>> author4.books.add(book5)
>>> exit()

C:\Users\Msys\OneDrive\Desktop\axox-acadmy\python Stack\django\django_intro\Project\Books_Authors(master -> origin)
(venv) λ python manage.py runserver
Watching for file changes with StatReloader
Performing system checks...

System check identified no issues (0 silenced).
September 27, 2022 - 15:38:47
Django version 4.1.1, using settings 'Books_Authors.settings'
Starting development server at http://127.0.0.1:8000/
Quit the server with CTRL-BREAK.
[27/Sep/2022 15:38:49] "GET / HTTP/1.1" 200 460
[27/Sep/2022 15:39:25] "GET / HTTP/1.1" 200 502
Not Found: /favicon.ico
[27/Sep/2022 15:39:25] "GET /favicon.ico HTTP/1.1" 404 2158
[27/Sep/2022 15:40:40] "GET / HTTP/1.1" 200 687
Not Found: /favicon.ico
[27/Sep/2022 15:40:40] "GET /favicon.ico HTTP/1.1" 404 2158
C:\Users\Msys\OneDrive\Desktop\axox-acadmy\python Stack\django\django_intro\Project\Books_Authors\library\views.py changed, reloading.
Watching for file changes with StatReloader
Performing system checks...

System check identified no issues (0 silenced).
September 27, 2022 - 15:41:48
Django version 4.1.1, using settings 'Books_Authors.settings'
Starting development server at http://127.0.0.1:8000/
Quit the server with CTRL-BREAK.
C:\Users\Msys\OneDrive\Desktop\axox-acadmy\python Stack\django\django_intro\Project\Books_Authors\library\views.py changed, reloading.
Watching for file changes with StatReloader
Performing system checks...

Exception in thread django-main-thread:
Traceback (most recent call last):
  File "C:\Users\Msys\AppData\Local\Programs\Python\Python310\lib\threading.py", line 1016, in _bootstrap_inner
    self.run()
  File "C:\Users\Msys\AppData\Local\Programs\Python\Python310\lib\threading.py", line 953, in run
    self._target(*self._args, **self._kwargs)
  File "C:\Users\Msys\OneDrive\Desktop\axox-acadmy\python Stack\django\django_intro\Project\venv\lib\site-packages\django\utils\autoreload.py", line 64, in wrapper
    fn(*args, **kwargs)
  File "C:\Users\Msys\OneDrive\Desktop\axox-acadmy\python Stack\django\django_intro\Project\venv\lib\site-packages\django\core\management\commands\runserver.py", line 134, in inner_run
    self.check(display_num_errors=True)
  File "C:\Users\Msys\OneDrive\Desktop\axox-acadmy\python Stack\django\django_intro\Project\venv\lib\site-packages\django\core\management\base.py", line 475, in check
    all_issues = checks.run_checks(
  File "C:\Users\Msys\OneDrive\Desktop\axox-acadmy\python Stack\django\django_intro\Project\venv\lib\site-packages\django\core\checks\registry.py", line 88, in run_checks
    new_errors = check(app_configs=app_configs, databases=databases)
  File "C:\Users\Msys\OneDrive\Desktop\axox-acadmy\python Stack\django\django_intro\Project\venv\lib\site-packages\django\core\checks\urls.py", line 14, in check_url_config
    return check_resolver(resolver)
  File "C:\Users\Msys\OneDrive\Desktop\axox-acadmy\python Stack\django\django_intro\Project\venv\lib\site-packages\django\core\checks\urls.py", line 24, in check_resolver
    return check_method()
  File "C:\Users\Msys\OneDrive\Desktop\axox-acadmy\python Stack\django\django_intro\Project\venv\lib\site-packages\django\urls\resolvers.py", line 494, in check
    for pattern in self.url_patterns:
  File "C:\Users\Msys\OneDrive\Desktop\axox-acadmy\python Stack\django\django_intro\Project\venv\lib\site-packages\django\utils\functional.py", line 57, in __get__
    res = instance.__dict__[self.name] = self.func(instance)
  File "C:\Users\Msys\OneDrive\Desktop\axox-acadmy\python Stack\django\django_intro\Project\venv\lib\site-packages\django\urls\resolvers.py", line 715, in url_patterns
    patterns = getattr(self.urlconf_module, "urlpatterns", self.urlconf_module)
  File "C:\Users\Msys\OneDrive\Desktop\axox-acadmy\python Stack\django\django_intro\Project\venv\lib\site-packages\django\utils\functional.py", line 57, in __get__
    res = instance.__dict__[self.name] = self.func(instance)
  File "C:\Users\Msys\OneDrive\Desktop\axox-acadmy\python Stack\django\django_intro\Project\venv\lib\site-packages\django\urls\resolvers.py", line 708, in urlconf_module
    return import_module(self.urlconf_name)
  File "C:\Users\Msys\AppData\Local\Programs\Python\Python310\lib\importlib\__init__.py", line 126, in import_module
    return _bootstrap._gcd_import(name[level:], package, level)
  File "<frozen importlib._bootstrap>", line 1050, in _gcd_import
  File "<frozen importlib._bootstrap>", line 1027, in _find_and_load
  File "<frozen importlib._bootstrap>", line 1006, in _find_and_load_unlocked
  File "<frozen importlib._bootstrap>", line 688, in _load_unlocked
  File "<frozen importlib._bootstrap_external>", line 883, in exec_module
  File "<frozen importlib._bootstrap>", line 241, in _call_with_frames_removed
  File "C:\Users\Msys\OneDrive\Desktop\axox-acadmy\python Stack\django\django_intro\Project\Books_Authors\Books_Authors\urls.py", line 20, in <module>
    path('',include('library.urls'))
  File "C:\Users\Msys\OneDrive\Desktop\axox-acadmy\python Stack\django\django_intro\Project\venv\lib\site-packages\django\urls\conf.py", line 38, in include
    urlconf_module = import_module(urlconf_module)
  File "C:\Users\Msys\AppData\Local\Programs\Python\Python310\lib\importlib\__init__.py", line 126, in import_module
    return _bootstrap._gcd_import(name[level:], package, level)
  File "<frozen importlib._bootstrap>", line 1050, in _gcd_import
  File "<frozen importlib._bootstrap>", line 1027, in _find_and_load
  File "<frozen importlib._bootstrap>", line 1006, in _find_and_load_unlocked
  File "<frozen importlib._bootstrap>", line 688, in _load_unlocked
  File "<frozen importlib._bootstrap_external>", line 883, in exec_module
  File "<frozen importlib._bootstrap>", line 241, in _call_with_frames_removed
  File "C:\Users\Msys\OneDrive\Desktop\axox-acadmy\python Stack\django\django_intro\Project\Books_Authors\library\urls.py", line 2, in <module>
    from . import views
  File "C:\Users\Msys\OneDrive\Desktop\axox-acadmy\python Stack\django\django_intro\Project\Books_Authors\library\views.py", line 8
    'author': Author.objects.all()
              ^^^^^^^^^^^^^^^^^^^^
SyntaxError: invalid syntax. Perhaps you forgot a comma?
C:\Users\Msys\OneDrive\Desktop\axox-acadmy\python Stack\django\django_intro\Project\Books_Authors\library\views.py changed, reloading.
Watching for file changes with StatReloader
Performing system checks...

Exception in thread django-main-thread:
Traceback (most recent call last):
  File "C:\Users\Msys\AppData\Local\Programs\Python\Python310\lib\threading.py", line 1016, in _bootstrap_inner
    self.run()
  File "C:\Users\Msys\AppData\Local\Programs\Python\Python310\lib\threading.py", line 953, in run
    self._target(*self._args, **self._kwargs)
  File "C:\Users\Msys\OneDrive\Desktop\axox-acadmy\python Stack\django\django_intro\Project\venv\lib\site-packages\django\utils\autoreload.py", line 64, in wrapper
    fn(*args, **kwargs)
  File "C:\Users\Msys\OneDrive\Desktop\axox-acadmy\python Stack\django\django_intro\Project\venv\lib\site-packages\django\core\management\commands\runserver.py", line 134, in inner_run
    self.check(display_num_errors=True)
  File "C:\Users\Msys\OneDrive\Desktop\axox-acadmy\python Stack\django\django_intro\Project\venv\lib\site-packages\django\core\management\base.py", line 475, in check
    all_issues = checks.run_checks(
  File "C:\Users\Msys\OneDrive\Desktop\axox-acadmy\python Stack\django\django_intro\Project\venv\lib\site-packages\django\core\checks\registry.py", line 88, in run_checks
    new_errors = check(app_configs=app_configs, databases=databases)
  File "C:\Users\Msys\OneDrive\Desktop\axox-acadmy\python Stack\django\django_intro\Project\venv\lib\site-packages\django\core\checks\urls.py", line 14, in check_url_config
    return check_resolver(resolver)
  File "C:\Users\Msys\OneDrive\Desktop\axox-acadmy\python Stack\django\django_intro\Project\venv\lib\site-packages\django\core\checks\urls.py", line 24, in check_resolver
    return check_method()
  File "C:\Users\Msys\OneDrive\Desktop\axox-acadmy\python Stack\django\django_intro\Project\venv\lib\site-packages\django\urls\resolvers.py", line 494, in check
    for pattern in self.url_patterns:
  File "C:\Users\Msys\OneDrive\Desktop\axox-acadmy\python Stack\django\django_intro\Project\venv\lib\site-packages\django\utils\functional.py", line 57, in __get__
    res = instance.__dict__[self.name] = self.func(instance)
  File "C:\Users\Msys\OneDrive\Desktop\axox-acadmy\python Stack\django\django_intro\Project\venv\lib\site-packages\django\urls\resolvers.py", line 715, in url_patterns
    patterns = getattr(self.urlconf_module, "urlpatterns", self.urlconf_module)
  File "C:\Users\Msys\OneDrive\Desktop\axox-acadmy\python Stack\django\django_intro\Project\venv\lib\site-packages\django\utils\functional.py", line 57, in __get__
    res = instance.__dict__[self.name] = self.func(instance)
  File "C:\Users\Msys\OneDrive\Desktop\axox-acadmy\python Stack\django\django_intro\Project\venv\lib\site-packages\django\urls\resolvers.py", line 708, in urlconf_module
    return import_module(self.urlconf_name)
  File "C:\Users\Msys\AppData\Local\Programs\Python\Python310\lib\importlib\__init__.py", line 126, in import_module
    return _bootstrap._gcd_import(name[level:], package, level)
  File "<frozen importlib._bootstrap>", line 1050, in _gcd_import
  File "<frozen importlib._bootstrap>", line 1027, in _find_and_load
  File "<frozen importlib._bootstrap>", line 1006, in _find_and_load_unlocked
  File "<frozen importlib._bootstrap>", line 688, in _load_unlocked
  File "<frozen importlib._bootstrap_external>", line 883, in exec_module
  File "<frozen importlib._bootstrap>", line 241, in _call_with_frames_removed
  File "C:\Users\Msys\OneDrive\Desktop\axox-acadmy\python Stack\django\django_intro\Project\Books_Authors\Books_Authors\urls.py", line 20, in <module>
    path('',include('library.urls'))
  File "C:\Users\Msys\OneDrive\Desktop\axox-acadmy\python Stack\django\django_intro\Project\venv\lib\site-packages\django\urls\conf.py", line 38, in include
    urlconf_module = import_module(urlconf_module)
  File "C:\Users\Msys\AppData\Local\Programs\Python\Python310\lib\importlib\__init__.py", line 126, in import_module
    return _bootstrap._gcd_import(name[level:], package, level)
  File "<frozen importlib._bootstrap>", line 1050, in _gcd_import
  File "<frozen importlib._bootstrap>", line 1027, in _find_and_load
  File "<frozen importlib._bootstrap>", line 1006, in _find_and_load_unlocked
  File "<frozen importlib._bootstrap>", line 688, in _load_unlocked
  File "<frozen importlib._bootstrap_external>", line 883, in exec_module
  File "<frozen importlib._bootstrap>", line 241, in _call_with_frames_removed
  File "C:\Users\Msys\OneDrive\Desktop\axox-acadmy\python Stack\django\django_intro\Project\Books_Authors\library\urls.py", line 2, in <module>
    from . import views
  File "C:\Users\Msys\OneDrive\Desktop\axox-acadmy\python Stack\django\django_intro\Project\Books_Authors\library\views.py", line 9
    \'relat'
     ^
SyntaxError: unexpected character after line continuation character
C:\Users\Msys\OneDrive\Desktop\axox-acadmy\python Stack\django\django_intro\Project\Books_Authors\library\views.py changed, reloading.
Watching for file changes with StatReloader
Performing system checks...

Exception in thread django-main-thread:
Traceback (most recent call last):
  File "C:\Users\Msys\AppData\Local\Programs\Python\Python310\lib\threading.py", line 1016, in _bootstrap_inner
    self.run()
  File "C:\Users\Msys\AppData\Local\Programs\Python\Python310\lib\threading.py", line 953, in run
    self._target(*self._args, **self._kwargs)
  File "C:\Users\Msys\OneDrive\Desktop\axox-acadmy\python Stack\django\django_intro\Project\venv\lib\site-packages\django\utils\autoreload.py", line 64, in wrapper
    fn(*args, **kwargs)
  File "C:\Users\Msys\OneDrive\Desktop\axox-acadmy\python Stack\django\django_intro\Project\venv\lib\site-packages\django\core\management\commands\runserver.py", line 134, in inner_run
    self.check(display_num_errors=True)
  File "C:\Users\Msys\OneDrive\Desktop\axox-acadmy\python Stack\django\django_intro\Project\venv\lib\site-packages\django\core\management\base.py", line 475, in check
    all_issues = checks.run_checks(
  File "C:\Users\Msys\OneDrive\Desktop\axox-acadmy\python Stack\django\django_intro\Project\venv\lib\site-packages\django\core\checks\registry.py", line 88, in run_checks
    new_errors = check(app_configs=app_configs, databases=databases)
  File "C:\Users\Msys\OneDrive\Desktop\axox-acadmy\python Stack\django\django_intro\Project\venv\lib\site-packages\django\core\checks\urls.py", line 14, in check_url_config
    return check_resolver(resolver)
  File "C:\Users\Msys\OneDrive\Desktop\axox-acadmy\python Stack\django\django_intro\Project\venv\lib\site-packages\django\core\checks\urls.py", line 24, in check_resolver
    return check_method()
  File "C:\Users\Msys\OneDrive\Desktop\axox-acadmy\python Stack\django\django_intro\Project\venv\lib\site-packages\django\urls\resolvers.py", line 494, in check
    for pattern in self.url_patterns:
  File "C:\Users\Msys\OneDrive\Desktop\axox-acadmy\python Stack\django\django_intro\Project\venv\lib\site-packages\django\utils\functional.py", line 57, in __get__
    res = instance.__dict__[self.name] = self.func(instance)
  File "C:\Users\Msys\OneDrive\Desktop\axox-acadmy\python Stack\django\django_intro\Project\venv\lib\site-packages\django\urls\resolvers.py", line 715, in url_patterns
    patterns = getattr(self.urlconf_module, "urlpatterns", self.urlconf_module)
  File "C:\Users\Msys\OneDrive\Desktop\axox-acadmy\python Stack\django\django_intro\Project\venv\lib\site-packages\django\utils\functional.py", line 57, in __get__
    res = instance.__dict__[self.name] = self.func(instance)
  File "C:\Users\Msys\OneDrive\Desktop\axox-acadmy\python Stack\django\django_intro\Project\venv\lib\site-packages\django\urls\resolvers.py", line 708, in urlconf_module
    return import_module(self.urlconf_name)
  File "C:\Users\Msys\AppData\Local\Programs\Python\Python310\lib\importlib\__init__.py", line 126, in import_module
    return _bootstrap._gcd_import(name[level:], package, level)
  File "<frozen importlib._bootstrap>", line 1050, in _gcd_import
  File "<frozen importlib._bootstrap>", line 1027, in _find_and_load
  File "<frozen importlib._bootstrap>", line 1006, in _find_and_load_unlocked
  File "<frozen importlib._bootstrap>", line 688, in _load_unlocked
  File "<frozen importlib._bootstrap_external>", line 883, in exec_module
  File "<frozen importlib._bootstrap>", line 241, in _call_with_frames_removed
  File "C:\Users\Msys\OneDrive\Desktop\axox-acadmy\python Stack\django\django_intro\Project\Books_Authors\Books_Authors\urls.py", line 20, in <module>
    path('',include('library.urls'))
  File "C:\Users\Msys\OneDrive\Desktop\axox-acadmy\python Stack\django\django_intro\Project\venv\lib\site-packages\django\urls\conf.py", line 38, in include
    urlconf_module = import_module(urlconf_module)
  File "C:\Users\Msys\AppData\Local\Programs\Python\Python310\lib\importlib\__init__.py", line 126, in import_module
    return _bootstrap._gcd_import(name[level:], package, level)
  File "<frozen importlib._bootstrap>", line 1050, in _gcd_import
  File "<frozen importlib._bootstrap>", line 1027, in _find_and_load
  File "<frozen importlib._bootstrap>", line 1006, in _find_and_load_unlocked
  File "<frozen importlib._bootstrap>", line 688, in _load_unlocked
  File "<frozen importlib._bootstrap_external>", line 883, in exec_module
  File "<frozen importlib._bootstrap>", line 241, in _call_with_frames_removed
  File "C:\Users\Msys\OneDrive\Desktop\axox-acadmy\python Stack\django\django_intro\Project\Books_Authors\library\urls.py", line 2, in <module>
    from . import views
  File "C:\Users\Msys\OneDrive\Desktop\axox-acadmy\python Stack\django\django_intro\Project\Books_Authors\library\views.py", line 8
    'author': Author.objects.all()
              ^^^^^^^^^^^^^^^^^^^^
SyntaxError: invalid syntax. Perhaps you forgot a comma?
C:\Users\Msys\OneDrive\Desktop\axox-acadmy\python Stack\django\django_intro\Project\Books_Authors\library\views.py changed, reloading.
Watching for file changes with StatReloader
Performing system checks...

Exception in thread django-main-thread:
Traceback (most recent call last):
  File "C:\Users\Msys\AppData\Local\Programs\Python\Python310\lib\threading.py", line 1016, in _bootstrap_inner
    self.run()
  File "C:\Users\Msys\AppData\Local\Programs\Python\Python310\lib\threading.py", line 953, in run
    self._target(*self._args, **self._kwargs)
  File "C:\Users\Msys\OneDrive\Desktop\axox-acadmy\python Stack\django\django_intro\Project\venv\lib\site-packages\django\utils\autoreload.py", line 64, in wrapper
    fn(*args, **kwargs)
  File "C:\Users\Msys\OneDrive\Desktop\axox-acadmy\python Stack\django\django_intro\Project\venv\lib\site-packages\django\core\management\commands\runserver.py", line 134, in inner_run
    self.check(display_num_errors=True)
  File "C:\Users\Msys\OneDrive\Desktop\axox-acadmy\python Stack\django\django_intro\Project\venv\lib\site-packages\django\core\management\base.py", line 475, in check
    all_issues = checks.run_checks(
  File "C:\Users\Msys\OneDrive\Desktop\axox-acadmy\python Stack\django\django_intro\Project\venv\lib\site-packages\django\core\checks\registry.py", line 88, in run_checks
    new_errors = check(app_configs=app_configs, databases=databases)
  File "C:\Users\Msys\OneDrive\Desktop\axox-acadmy\python Stack\django\django_intro\Project\venv\lib\site-packages\django\core\checks\urls.py", line 14, in check_url_config
    return check_resolver(resolver)
  File "C:\Users\Msys\OneDrive\Desktop\axox-acadmy\python Stack\django\django_intro\Project\venv\lib\site-packages\django\core\checks\urls.py", line 24, in check_resolver
    return check_method()
  File "C:\Users\Msys\OneDrive\Desktop\axox-acadmy\python Stack\django\django_intro\Project\venv\lib\site-packages\django\urls\resolvers.py", line 494, in check
    for pattern in self.url_patterns:
  File "C:\Users\Msys\OneDrive\Desktop\axox-acadmy\python Stack\django\django_intro\Project\venv\lib\site-packages\django\utils\functional.py", line 57, in __get__
    res = instance.__dict__[self.name] = self.func(instance)
  File "C:\Users\Msys\OneDrive\Desktop\axox-acadmy\python Stack\django\django_intro\Project\venv\lib\site-packages\django\urls\resolvers.py", line 715, in url_patterns
    patterns = getattr(self.urlconf_module, "urlpatterns", self.urlconf_module)
  File "C:\Users\Msys\OneDrive\Desktop\axox-acadmy\python Stack\django\django_intro\Project\venv\lib\site-packages\django\utils\functional.py", line 57, in __get__
    res = instance.__dict__[self.name] = self.func(instance)
  File "C:\Users\Msys\OneDrive\Desktop\axox-acadmy\python Stack\django\django_intro\Project\venv\lib\site-packages\django\urls\resolvers.py", line 708, in urlconf_module
    return import_module(self.urlconf_name)
  File "C:\Users\Msys\AppData\Local\Programs\Python\Python310\lib\importlib\__init__.py", line 126, in import_module
    return _bootstrap._gcd_import(name[level:], package, level)
  File "<frozen importlib._bootstrap>", line 1050, in _gcd_import
  File "<frozen importlib._bootstrap>", line 1027, in _find_and_load
  File "<frozen importlib._bootstrap>", line 1006, in _find_and_load_unlocked
  File "<frozen importlib._bootstrap>", line 688, in _load_unlocked
  File "<frozen importlib._bootstrap_external>", line 883, in exec_module
  File "<frozen importlib._bootstrap>", line 241, in _call_with_frames_removed
  File "C:\Users\Msys\OneDrive\Desktop\axox-acadmy\python Stack\django\django_intro\Project\Books_Authors\Books_Authors\urls.py", line 20, in <module>
    path('',include('library.urls'))
  File "C:\Users\Msys\OneDrive\Desktop\axox-acadmy\python Stack\django\django_intro\Project\venv\lib\site-packages\django\urls\conf.py", line 38, in include
    urlconf_module = import_module(urlconf_module)
  File "C:\Users\Msys\AppData\Local\Programs\Python\Python310\lib\importlib\__init__.py", line 126, in import_module
    return _bootstrap._gcd_import(name[level:], package, level)
  File "<frozen importlib._bootstrap>", line 1050, in _gcd_import
  File "<frozen importlib._bootstrap>", line 1027, in _find_and_load
  File "<frozen importlib._bootstrap>", line 1006, in _find_and_load_unlocked
  File "<frozen importlib._bootstrap>", line 688, in _load_unlocked
  File "<frozen importlib._bootstrap_external>", line 883, in exec_module
  File "<frozen importlib._bootstrap>", line 241, in _call_with_frames_removed
  File "C:\Users\Msys\OneDrive\Desktop\axox-acadmy\python Stack\django\django_intro\Project\Books_Authors\library\urls.py", line 2, in <module>
    from . import views
  File "C:\Users\Msys\OneDrive\Desktop\axox-acadmy\python Stack\django\django_intro\Project\Books_Authors\library\views.py", line 8
    'author': Author.objects.all()
              ^^^^^^^^^^^^^^^^^^^^
SyntaxError: invalid syntax. Perhaps you forgot a comma?
C:\Users\Msys\OneDrive\Desktop\axox-acadmy\python Stack\django\django_intro\Project\Books_Authors\library\views.py changed, reloading.
Watching for file changes with StatReloader
Performing system checks...

System check identified no issues (0 silenced).
September 27, 2022 - 15:48:48
Django version 4.1.1, using settings 'Books_Authors.settings'
Starting development server at http://127.0.0.1:8000/
Quit the server with CTRL-BREAK.